#VRML_SIM R2023b utf8

EXTERNPROTO "https://raw.githubusercontent.com/cyberbotics/webots/R2023b/projects/objects/backgrounds/protos/TexturedBackground.proto"
EXTERNPROTO "https://raw.githubusercontent.com/cyberbotics/webots/R2023b/projects/objects/backgrounds/protos/TexturedBackgroundLight.proto"
EXTERNPROTO "https://raw.githubusercontent.com/cyberbotics/webots/R2023b/projects/objects/floors/protos/RectangleArena.proto"
EXTERNPROTO "https://raw.githubusercontent.com/cyberbotics/webots/R2023b/projects/objects/drinks/protos/Can.proto"
EXTERNPROTO "https://raw.githubusercontent.com/cyberbotics/webots/R2023b/projects/objects/fruits/protos/Apple.proto"
EXTERNPROTO "https://raw.githubusercontent.com/cyberbotics/webots/R2023b/projects/objects/school_furniture/protos/Book.proto"
EXTERNPROTO "https://raw.githubusercontent.com/cyberbotics/webots/R2023b/projects/objects/obstacles/protos/OilBarrel.proto"
EXTERNPROTO "https://raw.githubusercontent.com/cyberbotics/webots/R2023b/projects/objects/balls/protos/SoccerBall.proto"

WorldInfo {
  info [
    "Example use of a color Camera device with auto-focusing capabilities."
  ]
  title "Camera With Auto-Focus"
}
Viewpoint {
  orientation 0.30949850710859556 -0.17556466492799985 -0.9345521507793291 4.181263109283716
  position 0.8564666783726814 -1.249853281795039 1.4343547959059741
}
TexturedBackground {
}
TexturedBackgroundLight {
}
RectangleArena {
  floorTileSize 0.25 0.25
  wallHeight 0.15
  wallAppearance PBRAppearance {
    baseColorMap ImageTexture {
      url [
        "https://raw.githubusercontent.com/cyberbotics/webots/R2023b/projects/default/worlds/textures/red_brick_wall.jpg"
      ]
    }
    roughness 1
    metalness 0
    textureTransform TextureTransform {
      scale 6 7
    }
  }
}
Robot {
  translation -0.0034940865937818284 0.0077321238243383515 -0.00022857860900239724
  rotation -0.014212695879308443 -0.011746878849055226 0.9998299906049767 -1.7603582346585451
  children [
    Pose {
      translation 0 0 0.0415
      rotation 0 0 1 -1.570796
      children [
        Shape {
          appearance PBRAppearance {
            baseColor 0.0820075 0.364731 0.8
            roughness 1
            metalness 0
          }
          geometry DEF BODY Cylinder {
            height 0.08
            radius 0.045
          }
        }
      ]
    }
    HingeJoint {
      jointParameters HingeJointParameters {
        position -76.0254294122486
        axis 0 1 0
        anchor 0 0 0.025
      }
      device [
        RotationalMotor {
          name "left wheel motor"
          consumptionFactor 70
        }
        PositionSensor {
          name "left wheel sensor"
        }
      ]
      endPoint Solid {
        translation 0 0.04499999999999999 0.025
        rotation 0.3986886426029548 -0.3986887169987396 -0.8258902307191388 1.7609333498758224
        children [
          DEF WHEEL Pose {
            rotation 0.577656895078166 0.5771968951617173 -0.5771968951617173 -2.093935
            children [
              Shape {
                appearance PBRAppearance {
                  baseColor 1 0 0
                  roughness 1
                  metalness 0
                }
                geometry Cylinder {
                  height 0.01
                  radius 0.025
                }
              }
            ]
          }
        ]
        name "left wheel"
        boundingObject USE WHEEL
        physics DEF PHYSICS_WHEEL Physics {
          density -1
          mass 0.05
        }
        linearVelocity 0.004411020565996886 0.022082855623846005 -1.3469579727204868e-08
        angularVelocity -0.9805723623500738 0.19631896119156306 0.5014268703684589
      }
    }
    HingeJoint {
      jointParameters HingeJointParameters {
        position 76.02541469920092
        axis 0 1 0
        anchor 0 0 0.025
      }
      device [
        RotationalMotor {
          name "right wheel motor"
          consumptionFactor 70
        }
        PositionSensor {
          name "right wheel sensor"
        }
      ]
      endPoint Solid {
        translation 0 -0.04499999999999999 0.025
        rotation -0.34478662205518723 0.3447865963097963 -0.8730660847019996 1.7061254748000063
        children [
          USE WHEEL
        ]
        name "right wheel"
        boundingObject USE WHEEL
        physics USE PHYSICS_WHEEL
        linearVelocity -0.004433665760315256 -0.022083153747807636 -2.706647961757428e-08
        angularVelocity 0.9805697774402855 -0.1963187557527169 0.5014271626619607
      }
    }
    DistanceSensor {
      translation 0.04 0 0.0915
      lookupTable [
        0 0 0
        1 1000 0
      ]
    }
    DEF SMILE Pose {
      translation 0.036 0 0.025
      rotation 0.25056300542381216 -0.9351130202419243 -0.25056300542381216 1.637834
      children [
        Shape {
          appearance PBRAppearance {
            baseColor 0.721569 0.290196 0.290196
            roughness 1
            metalness 0
          }
          geometry Cylinder {
            height 0.018
            radius 0.009
            subdivision 3
          }
        }
      ]
    }
    Camera {
      translation 0.04 0 0.0915
      children [
        Pose {
          translation -0.015 0 0
          rotation -0.5771968951617173 -0.577656895078166 -0.5771968951617173 -2.093935
          children [
            Shape {
              appearance PBRAppearance {
                roughness 1
                metalness 0
              }
              geometry Cylinder {
                height 0.03
                radius 0.01
              }
            }
          ]
        }
      ]
      fieldOfView 1
      width 400
      height 300
      focus Focus {
        focalDistance 0.21004123261026778
        focalLength 0.25
        maxFocalDistance 1
        minFocalDistance 0.1
      }
    }
    DEF RIGHT_EYE Pose {
      translation 0.042 0.02 0.063
      rotation 0.3871000691202075 0.6519791164167495 0.6519791164167495 2.40292
      children [
        Shape {
          appearance PBRAppearance {
            baseColor 0.975691 0.981481 0.0252992
            roughness 1
            metalness 0
          }
          geometry Cylinder {
            height 0.004
            radius 0.008
          }
        }
      ]
    }
    DEF LEFT_EYE Pose {
      translation 0.042 -0.02 0.063
      rotation 0.7664071928227091 0.45421311427685446 0.45421411427710606 1.83375
      children [
        Shape {
          appearance PBRAppearance {
            baseColor 0.975691 0.981481 0.0252992
            roughness 1
            metalness 0
          }
          geometry Cylinder {
            height 0.004
            radius 0.008
          }
        }
      ]
    }
  ]
  name "MyBot"
  boundingObject Pose {
    translation 0 0 0.0415
    rotation 0 0 1 -1.570796
    children [
      USE BODY
    ]
  }
  physics Physics {
    density -1
    mass 0.5
  }
  controller "camera_auto_focus"
  linearVelocity 0.00021884528721314417 -4.617311718093077e-05 -1.8732776652771405e-08
  angularVelocity -1.2876753982250273e-06 1.0012268481783487e-07 0.5001782493994898
}
Can {
  translation 0.28 1.6163437824185985e-19 0.06096171086093549
  rotation 3.3266256689820176e-17 -1.26456802543123e-17 1 -3.1415849999999996
}
Apple {
  translation -0.26 0 0.049764791394518226
}
Book {
  translation -0.08660299999999999 -0.29 0.09988239614048448
  rotation 3.446857946835864e-17 -2.934637512024818e-17 1 2.3562
}
OilBarrel {
  translation 0.143119 -0.169397 0.075
  rotation 0 0 1 1.5708
  height 0.2
  radius 0.05
}
SoccerBall {
  translation 0 0.29 0.11205723158604528
}
