#VRML_SIM R2023b utf8

EXTERNPROTO "https://raw.githubusercontent.com/cyberbotics/webots/R2023b/projects/objects/backgrounds/protos/TexturedBackground.proto"
EXTERNPROTO "https://raw.githubusercontent.com/cyberbotics/webots/R2023b/projects/objects/backgrounds/protos/TexturedBackgroundLight.proto"
EXTERNPROTO "https://raw.githubusercontent.com/cyberbotics/webots/R2023b/projects/objects/floors/protos/RectangleArena.proto"
EXTERNPROTO "https://raw.githubusercontent.com/cyberbotics/webots/R2023b/projects/objects/drinks/protos/Can.proto"
EXTERNPROTO "https://raw.githubusercontent.com/cyberbotics/webots/R2023b/projects/objects/fruits/protos/Apple.proto"
EXTERNPROTO "https://raw.githubusercontent.com/cyberbotics/webots/R2023b/projects/objects/fruits/protos/Orange.proto"
EXTERNPROTO "https://raw.githubusercontent.com/cyberbotics/webots/R2023b/projects/objects/kitchen/breakfast/protos/JamJar.proto"
EXTERNPROTO "https://raw.githubusercontent.com/cyberbotics/webots/R2023b/projects/objects/kitchen/breakfast/protos/CerealBox.proto"
EXTERNPROTO "https://raw.githubusercontent.com/cyberbotics/webots/R2023b/projects/objects/obstacles/protos/OilBarrel.proto"
EXTERNPROTO "https://raw.githubusercontent.com/cyberbotics/webots/R2023b/projects/objects/kitchen/breakfast/protos/BiscuitBox.proto"
EXTERNPROTO "https://raw.githubusercontent.com/cyberbotics/webots/R2023b/projects/objects/toys/protos/RubberDuck.proto"

WorldInfo {
  info [
    "Example use of a color Camera device with recognition capability."
  ]
  title "Camera Image Recognition"
}
Viewpoint {
  orientation 0.25038354870188595 -0.031793254089097125 -0.9676245488483002 3.012766974247319
  position 2.6221444113923926 0.2998707272666083 1.5539782879921704
}
TexturedBackground {
}
TexturedBackgroundLight {
}
RectangleArena {
  floorSize 1.5 1.5
}
Can {
  translation 0.267626 0.290201 0.0609617108609355
  rotation 0.6078229636147192 0.7886071931714658 0.09300505244793011 4.863450869639638e-17
}
Can {
  translation -0.326272 -0.341474 0.0609617108609355
  rotation 0.6078229636147192 0.7886071931714658 0.09300505244793011 4.863450869639638e-17
  name "can(1)"
}
Apple {
  translation -0.260886 0.22946 0.049764791394518226
}
Apple {
  translation -0.621889 0.56252 0.049764791394518226
  name "apple(1)"
}
DEF ORANGE Solid {
  translation -0.002188 -0.063045 0
  children [
    Orange {
      translation -0.187654 0.182317 0.04999764793150722
    }
  ]
  name "orange"
  recognitionColors [
    0.988235 0.686275 0.243137
  ]
}
DEF ORANGE Solid {
  translation 0.085807 -0.503005 0
  children [
    Orange {
      translation -0.187654 0.182317 0.04999764793150722
    }
  ]
  name "orange(1)"
  recognitionColors [
    0.988235 0.686275 0.243137
  ]
}
JamJar {
  translation -0.33681 0.078775 0
  mass 0
}
JamJar {
  translation 0.314033 -0.288298 0
  rotation 0 0 1 2.094395
  name "jam jar(1)"
  mass 0
}
CerealBox {
  translation -0.43865 0.194464 -0.00039201630959942446
  rotation 3.770103787649246e-17 2.407949098820323e-18 -1 0.523599
}
CerealBox {
  translation -0.45025899348281107 0.41529999585090943 -0.00039220694597741357
  rotation -7.438330797950161e-08 -2.0088280332138234e-06 -0.9999999999979794 0.7853985634923097
  name "cereal box(1)"
}
OilBarrel {
  translation -0.28712 -0.211927 0.07
  rotation 0 0 1 -1.5707953071795862
  height 0.14
  radius 0.06
}
OilBarrel {
  translation -0.240466 -0.485864 0.07
  rotation 0 0 1 -1.5707953071795862
  name "oil barrel(1)"
  height 0.14
  radius 0.06
}
OilBarrel {
  translation -0.464787 -0.437183 0.07
  rotation 0 0 1 -1.5707953071795862
  name "oil barrel(2)"
  height 0.14
  radius 0.06
}
BiscuitBox {
  translation 0.5384121770599435 -0.27466816841412345 0.03984308800740199
  rotation 0.6947462352857393 -0.18615610946793437 -0.694747127711986 -2.773493129695837
}
RubberDuck {
  translation -0.243817 0.384468 0.020436910949152134
  rotation -2.1881405658049035e-17 -2.92732624931207e-17 1 -2.356195307179586
}
Robot {
  translation 0.08377357233136416 0.0004958794180175356 -0.0002342114056777464
  rotation -0.014070370803902893 0.10483861472683499 0.9943897070704216 0.2683713332505515
  children [
    Pose {
      translation 0 0 0.0415
      children [
        Shape {
          appearance PBRAppearance {
            baseColor 0.0820075 0.364731 0.8
            roughness 1
            metalness 0
          }
          geometry DEF BODY Cylinder {
            height 0.08
            radius 0.045
          }
        }
      ]
    }
    HingeJoint {
      jointParameters HingeJointParameters {
        position -71.74586580287283
        axis 0 1 0
        anchor 0 0 0.025
      }
      device [
        RotationalMotor {
          name "left wheel motor"
          consumptionFactor 70
        }
        PositionSensor {
          name "left wheel sensor"
        }
      ]
      endPoint Solid {
        translation 0 0.04499999999999999 0.025
        rotation 0 -1 0 1.3323121167177905
        children [
          DEF WHEEL Pose {
            rotation -1 0 0 1.57
            children [
              Shape {
                appearance PBRAppearance {
                  baseColor 1 0 0
                  roughness 1
                  metalness 0
                }
                geometry Cylinder {
                  height 0.01
                  radius 0.025
                }
              }
            ]
          }
        ]
        name "left wheel"
        boundingObject USE WHEEL
        physics DEF PHYSICS_WHEEL Physics {
          density -1
          mass 0.05
        }
        linearVelocity -0.032695266580484106 -0.008534013056686624 1.677026225619547e-07
        angularVelocity 0.37715746539038586 -1.4518963699334433 0.7582164796806726
      }
    }
    HingeJoint {
      jointParameters HingeJointParameters {
        position 71.74583242841277
        axis 0 1 0
        anchor 0 0 0.025
      }
      device [
        RotationalMotor {
          name "right wheel motor"
          consumptionFactor 70
        }
        PositionSensor {
          name "right wheel sensor"
        }
      ]
      endPoint Solid {
        translation 0 -0.045 0.025
        rotation 0 1 0 4.326629356616904
        children [
          USE WHEEL
        ]
        name "right wheel"
        boundingObject USE WHEEL
        physics USE PHYSICS_WHEEL
        linearVelocity 0.03308566351437696 0.008533324489240116 1.1079536157855939e-07
        angularVelocity -0.3771629552482042 1.4519233469436799 0.7582189491898345
      }
    }
    DistanceSensor {
      translation 0.042 0.02 0.063
      rotation 0 0 -1 -0.499205
      children [
        DEF SENSOR Pose {
          rotation 0 1 0 1.57
          children [
            Shape {
              appearance PBRAppearance {
                baseColor 0.975691 0.981481 0.0252992
                roughness 1
                metalness 0
              }
              geometry Cylinder {
                height 0.004
                radius 0.008
              }
            }
          ]
        }
      ]
      name "ds0"
      lookupTable [
        0 1024 0
        0.05 1024 0
        0.15 0 0
      ]
      numberOfRays 2
      aperture 1
    }
    DistanceSensor {
      translation 0.042 -0.02 0.063
      rotation 0 0 1 -0.500795
      children [
        USE SENSOR
      ]
      name "ds1"
      lookupTable [
        0 1024 0
        0.05 1024 0
        0.15 0 0
      ]
      numberOfRays 2
      aperture 1
    }
    Shape {
      appearance PBRAppearance {
        baseColor 0.8 0.8 0.8
        baseColorMap ImageTexture {
          url [
            "https://raw.githubusercontent.com/cyberbotics/webots/R2023b/projects/samples/devices/worlds/textures/mybot.png"
          ]
        }
        roughness 0.5
        metalness 0
      }
      geometry IndexedFaceSet {
        coord Coordinate {
          point [
            0.0435 -0.015 0.038
            0.0435 -0.015 0.023
            0.0455 0 0.023
            0.0435 0.015 0.023
            0.0435 0.015 0.038
            0.0455 0 0.038
          ]
        }
        texCoord TextureCoordinate {
          point [
            0 0
            0.5 0
            1 0
            1 1
            0.5 1
            0 1
          ]
        }
        coordIndex [
          0, 1, 2, 5, -1, 5, 2, 3, 4, -1
        ]
        texCoordIndex [
          5, 0, 1, 4, -1, 4, 1, 2, 3, -1
        ]
        creaseAngle 0.9
      }
    }
    Camera {
      translation 0.04 0 0.0915
      children [
        Pose {
          translation -0.015 0 0
          rotation 0 -1 0 1.57
          children [
            Shape {
              appearance PBRAppearance {
                roughness 1
                metalness 0
              }
              geometry Cylinder {
                height 0.03
                radius 0.01
              }
            }
          ]
        }
      ]
      fieldOfView 1.0472
      width 256
      height 128
      antiAliasing TRUE
      recognition Recognition {
        frameColor 0.929412 0.831373 0
        frameThickness 3
        segmentation TRUE
      }
    }
    Display {
      name "segmented image display"
      width 256
      height 128
    }
  ]
  name "MyBot"
  boundingObject Pose {
    translation 0 0 0.0415
    children [
      USE BODY
    ]
  }
  physics Physics {
    density -1
    mass 0.5
  }
  controller "camera_segmentation"
  linearVelocity 0.00010666835063325957 0.00034094540331938255 6.390668062280929e-08
  angularVelocity -2.752859578167679e-06 1.3484982918423697e-05 0.7541233436737373
}
